Workbook

Sheet Overview
B2: UNZA | Health Insurance & NHIMA
B3: Ridgeway Campus student survey • 21 Aug – 29 Sep 2026 • 358 original responses • Report dated 02 Oct 2026
B5: Sex | F5: Year of study | J5: Programme | N5: Insurance registration
B6: All | F6: All | J6: All | N6: All
B7: Change the four yellow dropdowns to explore a cohort. All cards, dashboard charts and detailed summaries recalculate.
B9: RESPONDENTS | F9: ADEQUATE OVERALL | J9: MEAN OVERALL SCORE | N9: ADEQUATE NHIMA
B10: ='Cohort analysis'!C6 -> 358 | F10: ='Cohort analysis'!C8 -> 0.27932961 | J10: ='Cohort analysis'!C9 -> 9.7430168 | N10: ='Cohort analysis'!C15 -> 0.20786517
B12: ="Selected cohort | total 358" -> Selected cohort | total 358 | F12: ="n = "&'Cohort analysis'!C7&" | threshold "&Codebook!C8&"/19" -> n = 100 | threshold 12/19 | J12: ="Out of 19 correct answers" -> Out of 19 correct answers | N12: ="n = "&'Cohort analysis'!C14&" / "&'Cohort analysis'!C13&" valid" -> n = 74 / 356 valid
B14: HEALTH-INSURANCE ADEQUACY | F14: REGISTERED WITH INSURANCE | J14: SOCIAL-MEDIA REACH | N14: BENEFITS + LIMITATIONS
B15: ='Cohort analysis'!C11 -> 0.59217877 | F15: ='Cohort analysis'!C19 -> 0.38547486 | J15: ='Cohort analysis'!C21 -> 0.70391061 | N15: ='Cohort analysis'!C17 -> 6.1396648
B30: Rates use selected valid respondents. Programme rates are descriptive; full-sample tests are on Associations.
B44: Priority items are the five lowest B/C items in the full sample; cohort filters update their rates, not the selected item set. F2 sources are multi-select.
B46: Interpretation & next steps
B47: ="Full sample: 27.9% overall adequate; 20.8% NHIMA adequate. Current cohort: "&TEXT('Cohort analysis'!C8,"0.0%")&" overall adequate. Prioritise NHIMA orientation and targeted misconceptions." -> Full sample: 27.9% overall adequate; 20.8% NHIMA adequate. Current cohort: 27.9% overall adequate. Prioritise NHIMA orientation and targeted misconceptions.
B49: Provisional scoring key: validate policy-specific NHIMA answers before final use. NHIMA valid n = 356; overall n = 358 retains two incomplete C blocks with missing items scored zero.
B51: Cohort analysis | F51: Item results | J51: Associations | N51: Notes
B53: Responses | F53: Codebook
B55: Sources: supplied response workbook + UNZA analysis report dated 02 Oct 2026. Created 06 Oct 2026. All charts and formulas are native Excel; no macros.

Sheet Cohort analysis
B1: Back to dashboard
B2: Cohort analysis
B3: All results on this sheet follow the four dashboard dropdowns. Percentages use explicit valid-response denominators.
B5: Metric | C5: Value | D5: Denominator | E5: Definition
B6: Selected respondents | C6: =SUM('Responses'!$S$6:$S$363) -> 358 | D6: =C6 -> 358 | E6: Filter-matched survey records
B7: Adequate overall | C7: =SUMIFS('Responses'!$L$6:$L$363,'Responses'!$S$6:$S$363,1) -> 100 | D7: =C6 -> 358 | E7: Overall score meets editable threshold (default 12/19)
B8: Overall adequacy rate | C8: =IFERROR(C7/C6,0) -> 0.27932961 | D8: =C6 -> 358 | E8: All selected respondents, matching report convention
B9: Mean overall score | C9: =IFERROR(SUMIFS('Responses'!$K$6:$K$363,'Responses'!$S$6:$S$363,1)/C6,0) -> 9.7430168 | D9: =C6 -> 358 | E9: Score out of 19; missing C items contribute zero
B10: Adequate health insurance | C10: =COUNTIFS('Responses'!$I$6:$I$363,">="&Codebook!$C$6,'Responses'!$S$6:$S$363,1) -> 212 | D10: =C6 -> 358 | E10: B1–B10 threshold (default 6/10)
B11: Health-insurance adequacy rate | C11: =IFERROR(C10/C6,0) -> 0.59217877 | D11: =C6 -> 358 | E11: All selected respondents
B12: Mean health-insurance score | C12: =IFERROR(SUMIFS('Responses'!$I$6:$I$363,'Responses'!$S$6:$S$363,1)/C6,0) -> 5.5251397 | D12: =C6 -> 358 | E12: Score out of 10
B13: Valid NHIMA scores | C13: =SUMIFS('Responses'!$M$6:$M$363,'Responses'!$S$6:$S$363,1) -> 356 | D13: =C6 -> 358 | E13: Complete B/C records (B complete in source)
B14: Adequate NHIMA | C14: =COUNTIFS('Responses'!$J$6:$J$363,">="&Codebook!$C$7,'Responses'!$S$6:$S$363,1,'Responses'!$M$6:$M$363,1) -> 74 | D14: =C13 -> 356 | E14: C2–C10 threshold (default 6/9)
B15: NHIMA adequacy rate | C15: =IFERROR(C14/C13,0) -> 0.20786517 | D15: =C13 -> 356 | E15: Only respondents with complete NHIMA blocks
B16: Mean NHIMA score | C16: =IFERROR(SUMIFS('Responses'!$J$6:$J$363,'Responses'!$S$6:$S$363,1)/C13,0) -> 4.241573 | D16: =C13 -> 356 | E16: Score out of 9; missing blocks excluded
B17: Mean benefits + limitations | C17: =IFERROR(SUMIFS('Responses'!$P$6:$P$363,'Responses'!$S$6:$S$363,1)/C6,0) -> 6.1396648 | D17: =C6 -> 358 | E17: Score out of 14; not part of overall adequacy
B18: Registered with insurance | C18: =COUNTIFS('Responses'!$H$6:$H$363,"Yes",'Responses'!$S$6:$S$363,1) -> 138 | D18: =C6 -> 358 | E18: Any scheme, not necessarily NHIMA
B19: Insurance registration rate | C19: =IFERROR(C18/C6,0) -> 0.38547486 | D19: =C6 -> 358 | E19: Yes / all selected respondents
B20: Social media selected | C20: =SUMIFS('Responses'!$BE$6:$BE$363,'Responses'!$S$6:$S$363,1) -> 252 | D20: =C6 -> 358 | E20: Multi-select F2 source question
B21: Social media reach | C21: =IFERROR(C20/C6,0) -> 0.70391061 | D21: =C6 -> 358 | E21: May overlap with other information sources
B22: Wants more information | C22: =COUNTIFS('Responses'!$Q$6:$Q$363,"Yes",'Responses'!$S$6:$S$363,1) -> 158 | D22: =C23 -> 354 | E22: F4 response = Yes
B23: Valid information-interest responses | C23: =COUNTIFS('Responses'!$S$6:$S$363,1,'Responses'!$Q$6:$Q$363,"<>") -> 354 | D23: =C6 -> 358 | E23: Excludes four missing F4 responses
B24: Desire for more information rate | C24: =IFERROR(C22/C23,0) -> 0.44632768 | D24: =C23 -> 354 | E24: Yes / nonmissing F4 responses
B25: Incomplete NHIMA blocks | C25: =C6-C13 -> 2 | D25: =C6 -> 358 | E25: Missing C2–C10 responses
B27: Overall score SD | C27: =IFERROR(SQRT(MAX(0,(SUMPRODUCT('Responses'!$S$6:$S$363,'Responses'!$K$6:$K$363,'Responses'!$K$6:$K$363)-C6*C9^2)/(C6-1))),0) -> 3.7871808 | D27: =C6 -> 358 | E27: Sample standard deviation; zero shown if fewer than two respondents.
B28: Overall score median | C28: {=IFERROR(MEDIAN(IF('Responses'!$S$6:$S$363=1,'Responses'!$K$6:$K$363)),0)} -> 10 | D28: =C6 -> 358 | E28: Median of selected overall scores.
B29: Mean covered-benefit score | C29: =IFERROR(SUMIFS('Responses'!$N$6:$N$363,'Responses'!$S$6:$S$363,1)/C6,0) -> 4.3435754 | D29: =C6 -> 358 | E29: D1–D8 score out of 8.
B30: Mean limitations score | C30: =IFERROR(SUMIFS('Responses'!$O$6:$O$363,'Responses'!$S$6:$S$363,1)/C6,0) -> 1.7960894 | D30: =C6 -> 358 | E30: E1–E6 score out of 6.
B32: Domain adequacy
B33: Domain | C33: Adequate | D33: Valid n | E33: Adequate %
B34: Health insurance | C34: =C10 -> 212 | D34: =C6 -> 358 | E34: =IFERROR(C34/D34,0) -> 0.59217877 | K34: Health insurance
B35: NHIMA awareness | C35: =C14 -> 74 | D35: =C13 -> 356 | E35: =IFERROR(C35/D35,0) -> 0.20786517 | K35: NHIMA awareness
B36: Overall knowledge / awareness | C36: =C7 -> 100 | D36: =C6 -> 358 | E36: =IFERROR(C36/D36,0) -> 0.27932961 | K36: Overall
B40: Adequacy by programme
B41: Programme | C41: Selected n | D41: Adequate n | E41: Adequate %
B42: Public Health | C42: =COUNTIFS('Responses'!$G$6:$G$363,B42,'Responses'!$S$6:$S$363,1) -> 95 | D42: =SUMIFS('Responses'!$L$6:$L$363,'Responses'!$G$6:$G$363,B42,'Responses'!$S$6:$S$363,1) -> 35 | E42: =IFERROR(D42/C42,0) -> 0.36842105 | K42: Public Health
B43: Medicine | C43: =COUNTIFS('Responses'!$G$6:$G$363,B43,'Responses'!$S$6:$S$363,1) -> 55 | D43: =SUMIFS('Responses'!$L$6:$L$363,'Responses'!$G$6:$G$363,B43,'Responses'!$S$6:$S$363,1) -> 19 | E43: =IFERROR(D43/C43,0) -> 0.34545455 | K43: Medicine
B44: Nursing Sciences | C44: =COUNTIFS('Responses'!$G$6:$G$363,B44,'Responses'!$S$6:$S$363,1) -> 80 | D44: =SUMIFS('Responses'!$L$6:$L$363,'Responses'!$G$6:$G$363,B44,'Responses'!$S$6:$S$363,1) -> 22 | E44: =IFERROR(D44/C44,0) -> 0.275 | K44: Nursing
B45: Pharmacy | C45: =COUNTIFS('Responses'!$G$6:$G$363,B45,'Responses'!$S$6:$S$363,1) -> 64 | D45: =SUMIFS('Responses'!$L$6:$L$363,'Responses'!$G$6:$G$363,B45,'Responses'!$S$6:$S$363,1) -> 17 | E45: =IFERROR(D45/C45,0) -> 0.265625 | K45: Pharmacy
B46: Other Ridgeway Health Sciences programme | C46: =COUNTIFS('Responses'!$G$6:$G$363,B46,'Responses'!$S$6:$S$363,1) -> 64 | D46: =SUMIFS('Responses'!$L$6:$L$363,'Responses'!$G$6:$G$363,B46,'Responses'!$S$6:$S$363,1) -> 7 | E46: =IFERROR(D46/C46,0) -> 0.109375 | K46: Other health sciences
...

Sheet Item results
B1: Back to dashboard
B2: Item-level knowledge gaps
B3: Follows the dashboard filters. Correct-answer rates exclude missing responses; incorrect and Not sure remain in the denominator.
B5: Priority: use the lowest-scoring items to focus NHIMA orientation on benefit scope, accreditation and common insurance misconceptions. All correct-answer labels are provisional.
B7: Item | C7: Domain | D7: Question / concept | E7: Key | F7: Selected n | G7: Answered n | H7: Correct n | I7: Correct % | J7: Incorrect n | K7: Not sure n | L7: Missing n | M7: Not sure %
B8: B1 | C8: Health insurance | D8: Meaning of health insurance | E8: =Codebook!F13 -> True | F8: ='Cohort analysis'!C6 -> 358 | G8: =COUNTIFS('Responses'!$S$6:$S$363,1,'Responses'!$T$6:$T$363,"<>") -> 358 | H8: =SUMIFS('Responses'!$BL$6:$BL$363,'Responses'!$S$6:$S$363,1) -> 304 | I8: =IFERROR(H8/G8,0) -> 0.84916201 | J8: =G8-H8-K8 -> 30 | K8: =COUNTIFS('Responses'!$T$6:$T$363,"Not sure",'Responses'!$S$6:$S$363,1) -> 24 | L8: =F8-G8 -> 0 | M8: =IFERROR(K8/G8,0) -> 0.067039106
B9: B2 | C9: Health insurance | D9: Reimbursement-only misconception | E9: =Codebook!F14 -> False | F9: ='Cohort analysis'!C6 -> 358 | G9: =COUNTIFS('Responses'!$S$6:$S$363,1,'Responses'!$U$6:$U$363,"<>") -> 358 | H9: =SUMIFS('Responses'!$BM$6:$BM$363,'Responses'!$S$6:$S$363,1) -> 56 | I9: =IFERROR(H9/G9,0) -> 0.15642458 | J9: =G9-H9-K9 -> 257 | K9: =COUNTIFS('Responses'!$U$6:$U$363,"Not sure",'Responses'!$S$6:$S$363,1) -> 45 | L9: =F9-G9 -> 0 | M9: =IFERROR(K9/G9,0) -> 0.12569832
B10: B3 | C10: Health insurance | D10: Insurance for sick people only | E10: =Codebook!F15 -> False | F10: ='Cohort analysis'!C6 -> 358 | G10: =COUNTIFS('Responses'!$S$6:$S$363,1,'Responses'!$V$6:$V$363,"<>") -> 358 | H10: =SUMIFS('Responses'!$BN$6:$BN$363,'Responses'!$S$6:$S$363,1) -> 83 | I10: =IFERROR(H10/G10,0) -> 0.23184358 | J10: =G10-H10-K10 -> 235 | K10: =COUNTIFS('Responses'!$V$6:$V$363,"Not sure",'Responses'!$S$6:$S$363,1) -> 40 | L10: =F10-G10 -> 0 | M10: =IFERROR(K10/G10,0) -> 0.11173184
B11: B4 | C11: Health insurance | D11: Monthly contributions | E11: =Codebook!F16 -> True | F11: ='Cohort analysis'!C6 -> 358 | G11: =COUNTIFS('Responses'!$S$6:$S$363,1,'Responses'!$W$6:$W$363,"<>") -> 358 | H11: =SUMIFS('Responses'!$BO$6:$BO$363,'Responses'!$S$6:$S$363,1) -> 280 | I11: =IFERROR(H11/G11,0) -> 0.78212291 | J11: =G11-H11-K11 -> 35 | K11: =COUNTIFS('Responses'!$W$6:$W$363,"Not sure",'Responses'!$S$6:$S$363,1) -> 43 | L11: =F11-G11 -> 0 | M11: =IFERROR(K11/G11,0) -> 0.12011173
B12: B5 | C12: Health insurance | D12: Salary deductions | E12: =Codebook!F17 -> True | F12: ='Cohort analysis'!C6 -> 358 | G12: =COUNTIFS('Responses'!$S$6:$S$363,1,'Responses'!$X$6:$X$363,"<>") -> 358 | H12: =SUMIFS('Responses'!$BP$6:$BP$363,'Responses'!$S$6:$S$363,1) -> 274 | I12: =IFERROR(H12/G12,0) -> 0.76536313 | J12: =G12-H12-K12 -> 36 | K12: =COUNTIFS('Responses'!$X$6:$X$363,"Not sure",'Responses'!$S$6:$S$363,1) -> 48 | L12: =F12-G12 -> 0 | M12: =IFERROR(K12/G12,0) -> 0.13407821
B13: B6 | C13: Health insurance | D13: Eligibility outside formal employment | E13: =Codebook!F18 -> False | F13: ='Cohort analysis'!C6 -> 358 | G13: =COUNTIFS('Responses'!$S$6:$S$363,1,'Responses'!$Y$6:$Y$363,"<>") -> 358 | H13: =SUMIFS('Responses'!$BQ$6:$BQ$363,'Responses'!$S$6:$S$363,1) -> 93 | I13: =IFERROR(H13/G13,0) -> 0.25977654 | J13: =G13-H13-K13 -> 208 | K13: =COUNTIFS('Responses'!$Y$6:$Y$363,"Not sure",'Responses'!$S$6:$S$363,1) -> 57 | L13: =F13-G13 -> 0 | M13: =IFERROR(K13/G13,0) -> 0.15921788
B14: B7 | C14: Health insurance | D14: Reduced out-of-pocket costs | E14: =Codebook!F19 -> True | F14: ='Cohort analysis'!C6 -> 358 | G14: =COUNTIFS('Responses'!$S$6:$S$363,1,'Responses'!$Z$6:$Z$363,"<>") -> 358 | H14: =SUMIFS('Responses'!$BR$6:$BR$363,'Responses'!$S$6:$S$363,1) -> 284 | I14: =IFERROR(H14/G14,0) -> 0.79329609 | J14: =G14-H14-K14 -> 27 | K14: =COUNTIFS('Responses'!$Z$6:$Z$363,"Not sure",'Responses'!$S$6:$S$363,1) -> 47 | L14: =F14-G14 -> 0 | M14: =IFERROR(K14/G14,0) -> 0.13128492
B15: B8 | C15: Health insurance | D15: Membership proof at facility | E15: =Codebook!F20 -> True | F15: ='Cohort analysis'!C6 -> 358 | G15: =COUNTIFS('Responses'!$S$6:$S$363,1,'Responses'!$AA$6:$AA$363,"<>") -> 358 | H15: =SUMIFS('Responses'!$BS$6:$BS$363,'Responses'!$S$6:$S$363,1) -> 261 | I15: =IFERROR(H15/G15,0) -> 0.72905028 | J15: =G15-H15-K15 -> 31 | K15: =COUNTIFS('Responses'!$AA$6:$AA$363,"Not sure",'Responses'!$S$6:$S$363,1) -> 66 | L15: =F15-G15 -> 0 | M15: =IFERROR(K15/G15,0) -> 0.18435754
B16: B9 | C16: Health insurance | D16: Universal facility acceptance | E16: =Codebook!F21 -> False | F16: ='Cohort analysis'!C6 -> 358 | G16: =COUNTIFS('Responses'!$S$6:$S$363,1,'Responses'!$AB$6:$AB$363,"<>") -> 358 | H16: =SUMIFS('Responses'!$BT$6:$BT$363,'Responses'!$S$6:$S$363,1) -> 79 | I16: =IFERROR(H16/G16,0) -> 0.22067039 | J16: =G16-H16-K16 -> 205 | K16: =COUNTIFS('Responses'!$AB$6:$AB$363,"Not sure",'Responses'!$S$6:$S$363,1) -> 74 | L16: =F16-G16 -> 0 | M16: =IFERROR(K16/G16,0) -> 0.20670391
B17: B10 | C17: Health insurance | D17: Registration before claims | E17: =Codebook!F22 -> True | F17: ='Cohort analysis'!C6 -> 358 | G17: =COUNTIFS('Responses'!$S$6:$S$363,1,'Responses'!$AC$6:$AC$363,"<>") -> 358 | H17: =SUMIFS('Responses'!$BU$6:$BU$363,'Responses'!$S$6:$S$363,1) -> 264 | I17: =IFERROR(H17/G17,0) -> 0.73743017 | J17: =G17-H17-K17 -> 31 | K17: =COUNTIFS('Responses'!$AC$6:$AC$363,"Not sure",'Responses'!$S$6:$S$363,1) -> 63 | L17: =F17-G17 -> 0 | M17: =IFERROR(K17/G17,0) -> 0.17597765
B18: C2 | C18: NHIMA awareness | D18: National scheme management | E18: =Codebook!F23 -> True | F18: ='Cohort analysis'!C6 -> 358 | G18: =COUNTIFS('Responses'!$S$6:$S$363,1,'Responses'!$AD$6:$AD$363,"<>") -> 356 | H18: =SUMIFS('Responses'!$BV$6:$BV$363,'Responses'!$S$6:$S$363,1) -> 265 | I18: =IFERROR(H18/G18,0) -> 0.74438202 | J18: =G18-H18-K18 -> 19 | K18: =COUNTIFS('Responses'!$AD$6:$AD$363,"Not sure",'Responses'!$S$6:$S$363,1) -> 72 | L18: =F18-G18 -> 2 | M18: =IFERROR(K18/G18,0) -> 0.20224719
B19: C3 | C19: NHIMA awareness | D19: Established by Act of Parliament | E19: =Codebook!F24 -> True | F19: ='Cohort analysis'!C6 -> 358 | G19: =COUNTIFS('Responses'!$S$6:$S$363,1,'Responses'!$AE$6:$AE$363,"<>") -> 356 | H19: =SUMIFS('Responses'!$BW$6:$BW$363,'Responses'!$S$6:$S$363,1) -> 239 | I19: =IFERROR(H19/G19,0) -> 0.67134831 | J19: =G19-H19-K19 -> 25 | K19: =COUNTIFS('Responses'!$AE$6:$AE$363,"Not sure",'Responses'!$S$6:$S$363,1) -> 92 | L19: =F19-G19 -> 2 | M19: =IFERROR(K19/G19,0) -> 0.25842697
B20: C4 | C20: NHIMA awareness | D20: Formal-employment-only registration | E20: =Codebook!F25 -> False | F20: ='Cohort analysis'!C6 -> 358 | G20: =COUNTIFS('Responses'!$S$6:$S$363,1,'Responses'!$AF$6:$AF$363,"<>") -> 356 | H20: =SUMIFS('Responses'!$BX$6:$BX$363,'Responses'!$S$6:$S$363,1) -> 99 | I20: =IFERROR(H20/G20,0) -> 0.27808989 | J20: =G20-H20-K20 -> 192 | K20: =COUNTIFS('Responses'!$AF$6:$AF$363,"Not sure",'Responses'!$S$6:$S$363,1) -> 65 | L20: =F20-G20 -> 2 | M20: =IFERROR(K20/G20,0) -> 0.18258427
B21: C5 | C21: NHIMA awareness | D21: Employer matching contributions | E21: =Codebook!F26 -> True | F21: ='Cohort analysis'!C6 -> 358 | G21: =COUNTIFS('Responses'!$S$6:$S$363,1,'Responses'!$AG$6:$AG$363,"<>") -> 356 | H21: =SUMIFS('Responses'!$BY$6:$BY$363,'Responses'!$S$6:$S$363,1) -> 201 | I21: =IFERROR(H21/G21,0) -> 0.56460674 | J21: =G21-H21-K21 -> 58 | K21: =COUNTIFS('Responses'!$AG$6:$AG$363,"Not sure",'Responses'!$S$6:$S$363,1) -> 97 | L21: =F21-G21 -> 2 | M21: =IFERROR(K21/G21,0) -> 0.27247191
B22: C6 | C22: NHIMA awareness | D22: Membership cards | E22: =Codebook!F27 -> True | F22: ='Cohort analysis'!C6 -> 358 | G22: =COUNTIFS('Responses'!$S$6:$S$363,1,'Responses'!$AH$6:$AH$363,"<>") -> 356 | H22: =SUMIFS('Responses'!$BZ$6:$BZ$363,'Responses'!$S$6:$S$363,1) -> 227 | I22: =IFERROR(H22/G22,0) -> 0.63764045 | J22: =G22-H22-K22 -> 36 | K22: =COUNTIFS('Responses'!$AH$6:$AH$363,"Not sure",'Responses'!$S$6:$S$363,1) -> 93 | L22: =F22-G22 -> 2 | M22: =IFERROR(K22/G22,0) -> 0.26123596
B23: C7 | C23: NHIMA awareness | D23: Access at non-accredited facilities | E23: =Codebook!F28 -> False | F23: ='Cohort analysis'!C6 -> 358 | G23: =COUNTIFS('Responses'!$S$6:$S$363,1,'Responses'!$AI$6:$AI$363,"<>") -> 356 | H23: =SUMIFS('Responses'!$CA$6:$CA$363,'Responses'!$S$6:$S$363,1) -> 76 | I23: =IFERROR(H23/G23,0) -> 0.21348315 | J23: =G23-H23-K23 -> 196 | K23: =COUNTIFS('Responses'!$AI$6:$AI$363,"Not sure",'Responses'!$S$6:$S$363,1) -> 84 | L23: =F23-G23 -> 2 | M23: =IFERROR(K23/G23,0) -> 0.23595506
B24: C8 | C24: NHIMA awareness | D24: Curative-only coverage misconception | E24: =Codebook!F29 -> False | F24: ='Cohort analysis'!C6 -> 358 | G24: =COUNTIFS('Responses'!$S$6:$S$363,1,'Responses'!$AJ$6:$AJ$363,"<>") -> 356 | H24: =SUMIFS('Responses'!$CB$6:$CB$363,'Responses'!$S$6:$S$363,1) -> 42 | I24: =IFERROR(H24/G24,0) -> 0.11797753 | J24: =G24-H24-K24 -> 215 | K24: =COUNTIFS('Responses'!$AJ$6:$AJ$363,"Not sure",'Responses'!$S$6:$S$363,1) -> 99 | L24: =F24-G24 -> 2 | M24: =IFERROR(K24/G24,0) -> 0.27808989
B25: C9 | C25: NHIMA awareness | D25: Online status checks | E25: =Codebook!F30 -> True | F25: ='Cohort analysis'!C6 -> 358 | G25: =COUNTIFS('Responses'!$S$6:$S$363,1,'Responses'!$AK$6:$AK$363,"<>") -> 356 | H25: =SUMIFS('Responses'!$CC$6:$CC$363,'Responses'!$S$6:$S$363,1) -> 235 | I25: =IFERROR(H25/G25,0) -> 0.66011236 | J25: =G25-H25-K25 -> 26 | K25: =COUNTIFS('Responses'!$AK$6:$AK$363,"Not sure",'Responses'!$S$6:$S$363,1) -> 95 | L25: =F25-G25 -> 2 | M25: =IFERROR(K25/G25,0) -> 0.26685393
B26: C10 | C26: NHIMA awareness | D26: NHIMA as the only insurance option | E26: =Codebook!F31 -> False | F26: ='Cohort analysis'!C6 -> 358 | G26: =COUNTIFS('Responses'!$S$6:$S$363,1,'Responses'!$AL$6:$AL$363,"<>") -> 356 | H26: =SUMIFS('Responses'!$CD$6:$CD$363,'Responses'!$S$6:$S$363,1) -> 126 | I26: =IFERROR(H26/G26,0) -> 0.35393258 | J26: =G26-H26-K26 -> 159 | K26: =COUNTIFS('Responses'!$AL$6:$AL$363,"Not sure",'Responses'!$S$6:$S$363,1) -> 71 | L26: =F26-G26 -> 2 | M26: =IFERROR(K26/G26,0) -> 0.1994382
B27: D1 | C27: Covered benefits | D27: Doctor consultation | E27: =Codebook!F32 -> Covered | F27: ='Cohort analysis'!C6 -> 358 | G27: =COUNTIFS('Responses'!$S$6:$S$363,1,'Responses'!$AM$6:$AM$363,"<>") -> 358 | H27: =SUMIFS('Responses'!$CE$6:$CE$363,'Responses'!$S$6:$S$363,1) -> 205 | I27: =IFERROR(H27/G27,0) -> 0.5726257 | J27: =G27-H27-K27 -> 53 | K27: =COUNTIFS('Responses'!$AM$6:$AM$363,"Not sure",'Responses'!$S$6:$S$363,1) -> 100 | L27: =F27-G27 -> 0 | M27: =IFERROR(K27/G27,0) -> 0.27932961
B28: D2 | C28: Covered benefits | D28: Hospital admission | E28: =Codebook!F33 -> Covered | F28: ='Cohort analysis'!C6 -> 358 | G28: =COUNTIFS('Responses'!$S$6:$S$363,1,'Responses'!$AN$6:$AN$363,"<>") -> 358 | H28: =SUMIFS('Responses'!$CF$6:$CF$363,'Responses'!$S$6:$S$363,1) -> 202 | I28: =IFERROR(H28/G28,0) -> 0.56424581 | J28: =G28-H28-K28 -> 71 | K28: =COUNTIFS('Responses'!$AN$6:$AN$363,"Not sure",'Responses'!$S$6:$S$363,1) -> 85 | L28: =F28-G28 -> 0 | M28: =IFERROR(K28/G28,0) -> 0.23743017
B29: D3 | C29: Covered benefits | D29: Basic laboratory tests | E29: =Codebook!F34 -> Covered | F29: ='Cohort analysis'!C6 -> 358 | G29: =COUNTIFS('Responses'!$S$6:$S$363,1,'Responses'!$AO$6:$AO$363,"<>") -> 358 | H29: =SUMIFS('Responses'!$CG$6:$CG$363,'Responses'!$S$6:$S$363,1) -> 191 | I29: =IFERROR(H29/G29,0) -> 0.53351955 | J29: =G29-H29-K29 -> 63 | K29: =COUNTIFS('Responses'!$AO$6:$AO$363,"Not sure",'Responses'!$S$6:$S$363,1) -> 104 | L29: =F29-G29 -> 0 | M29: =IFERROR(K29/G29,0) -> 0.29050279
B30: D4 | C30: Covered benefits | D30: Prescribed medicines | E30: =Codebook!F35 -> Covered | F30: ='Cohort analysis'!C6 -> 358 | G30: =COUNTIFS('Responses'!$S$6:$S$363,1,'Responses'!$AP$6:$AP$363,"<>") -> 358 | H30: =SUMIFS('Responses'!$CH$6:$CH$363,'Responses'!$S$6:$S$363,1) -> 201 | I30: =IFERROR(H30/G30,0) -> 0.56145251 | J30: =G30-H30-K30 -> 54 | K30: =COUNTIFS('Responses'!$AP$6:$AP$363,"Not sure",'Responses'!$S$6:$S$363,1) -> 103 | L30: =F30-G30 -> 0 | M30: =IFERROR(K30/G30,0) -> 0.2877095
B31: D5 | C31: Covered benefits | D31: Maternity / childbirth care | E31: =Codebook!F36 -> Covered | F31: ='Cohort analysis'!C6 -> 358 | G31: =COUNTIFS('Responses'!$S$6:$S$363,1,'Responses'!$AQ$6:$AQ$363,"<>") -> 358 | H31: =SUMIFS('Responses'!$CI$6:$CI$363,'Responses'!$S$6:$S$363,1) -> 189 | I31: =IFERROR(H31/G31,0) -> 0.52793296 | J31: =G31-H31-K31 -> 55 | K31: =COUNTIFS('Responses'!$AQ$6:$AQ$363,"Not sure",'Responses'!$S$6:$S$363,1) -> 114 | L31: =F31-G31 -> 0 | M31: =IFERROR(K31/G31,0) -> 0.31843575
B32: D6 | C32: Covered benefits | D32: Emergency care | E32: =Codebook!F37 -> Covered | F32: ='Cohort analysis'!C6 -> 358 | G32: =COUNTIFS('Responses'!$S$6:$S$363,1,'Responses'!$AR$6:$AR$363,"<>") -> 358 | H32: =SUMIFS('Responses'!$CJ$6:$CJ$363,'Responses'!$S$6:$S$363,1) -> 198 | I32: =IFERROR(H32/G32,0) -> 0.55307263 | J32: =G32-H32-K32 -> 48 | K32: =COUNTIFS('Responses'!$AR$6:$AR$363,"Not sure",'Responses'!$S$6:$S$363,1) -> 112 | L32: =F32-G32 -> 0 | M32: =IFERROR(K32/G32,0) -> 0.31284916
B33: D7 | C33: Covered benefits | D33: Chronic-condition follow-up | E33: =Codebook!F38 -> Covered | F33: ='Cohort analysis'!C6 -> 358 | G33: =COUNTIFS('Responses'!$S$6:$S$363,1,'Responses'!$AS$6:$AS$363,"<>") -> 358 | H33: =SUMIFS('Responses'!$CK$6:$CK$363,'Responses'!$S$6:$S$363,1) -> 192 | I33: =IFERROR(H33/G33,0) -> 0.53631285 | J33: =G33-H33-K33 -> 56 | K33: =COUNTIFS('Responses'!$AS$6:$AS$363,"Not sure",'Responses'!$S$6:$S$363,1) -> 110 | L33: =F33-G33 -> 0 | M33: =IFERROR(K33/G33,0) -> 0.30726257
B34: D8 | C34: Covered benefits | D34: Rehabilitative care | E34: =Codebook!F39 -> Covered | F34: ='Cohort analysis'!C6 -> 358 | G34: =COUNTIFS('Responses'!$S$6:$S$363,1,'Responses'!$AT$6:$AT$363,"<>") -> 358 | H34: =SUMIFS('Responses'!$CL$6:$CL$363,'Responses'!$S$6:$S$363,1) -> 177 | I34: =IFERROR(H34/G34,0) -> 0.49441341 | J34: =G34-H34-K34 -> 45 | K34: =COUNTIFS('Responses'!$AT$6:$AT$363,"Not sure",'Responses'!$S$6:$S$363,1) -> 136 | L34: =F34-G34 -> 0 | M34: =IFERROR(K34/G34,0) -> 0.37988827
B35: E1 | C35: Limitations | D35: Non-accredited facility treatment | E35: =Codebook!F40 -> Not covered | F35: ='Cohort analysis'!C6 -> 358 | G35: =COUNTIFS('Responses'!$S$6:$S$363,1,'Responses'!$AU$6:$AU$363,"<>") -> 358 | H35: =SUMIFS('Responses'!$CM$6:$CM$363,'Responses'!$S$6:$S$363,1) -> 116 | I35: =IFERROR(H35/G35,0) -> 0.32402235 | J35: =G35-H35-K35 -> 124 | K35: =COUNTIFS('Responses'!$AU$6:$AU$363,"Not sure",'Responses'!$S$6:$S$363,1) -> 118 | L35: =F35-G35 -> 0 | M35: =IFERROR(K35/G35,0) -> 0.32960894
B36: E2 | C36: Limitations | D36: Purely cosmetic procedures | E36: =Codebook!F41 -> Not covered | F36: ='Cohort analysis'!C6 -> 358 | G36: =COUNTIFS('Responses'!$S$6:$S$363,1,'Responses'!$AV$6:$AV$363,"<>") -> 358 | H36: =SUMIFS('Responses'!$CN$6:$CN$363,'Responses'!$S$6:$S$363,1) -> 110 | I36: =IFERROR(H36/G36,0) -> 0.30726257 | J36: =G36-H36-K36 -> 127 | K36: =COUNTIFS('Responses'!$AV$6:$AV$363,"Not sure",'Responses'!$S$6:$S$363,1) -> 121 | L36: =F36-G36 -> 0 | M36: =IFERROR(K36/G36,0) -> 0.33798883
B37: E3 | C37: Limitations | D37: Specialist care without referral | E37: =Codebook!F42 -> Not covered | F37: ='Cohort analysis'!C6 -> 358 | G37: =COUNTIFS('Responses'!$S$6:$S$363,1,'Responses'!$AW$6:$AW$363,"<>") -> 358 | H37: =SUMIFS('Responses'!$CO$6:$CO$363,'Responses'!$S$6:$S$363,1) -> 98 | I37: =IFERROR(H37/G37,0) -> 0.27374302 | J37: =G37-H37-K37 -> 125 | K37: =COUNTIFS('Responses'!$AW$6:$AW$363,"Not sure",'Responses'!$S$6:$S$363,1) -> 135 | L37: =F37-G37 -> 0 | M37: =IFERROR(K37/G37,0) -> 0.37709497
B38: E4 | C38: Limitations | D38: Overseas care without authorisation | E38: =Codebook!F43 -> Not covered | F38: ='Cohort analysis'!C6 -> 358 | G38: =COUNTIFS('Responses'!$S$6:$S$363,1,'Responses'!$AX$6:$AX$363,"<>") -> 358 | H38: =SUMIFS('Responses'!$CP$6:$CP$363,'Responses'!$S$6:$S$363,1) -> 107 | I38: =IFERROR(H38/G38,0) -> 0.29888268 | J38: =G38-H38-K38 -> 113 | K38: =COUNTIFS('Responses'!$AX$6:$AX$363,"Not sure",'Responses'!$S$6:$S$363,1) -> 138 | L38: =F38-G38 -> 0 | M38: =IFERROR(K38/G38,0) -> 0.38547486
B39: E5 | C39: Limitations | D39: Lapsed contributions | E39: =Codebook!F44 -> Not covered | F39: ='Cohort analysis'!C6 -> 358 | G39: =COUNTIFS('Responses'!$S$6:$S$363,1,'Responses'!$AY$6:$AY$363,"<>") -> 358 | H39: =SUMIFS('Responses'!$CQ$6:$CQ$363,'Responses'!$S$6:$S$363,1) -> 103 | I39: =IFERROR(H39/G39,0) -> 0.2877095 | J39: =G39-H39-K39 -> 111 | K39: =COUNTIFS('Responses'!$AY$6:$AY$363,"Not sure",'Responses'!$S$6:$S$363,1) -> 144 | L39: =F39-G39 -> 0 | M39: =IFERROR(K39/G39,0) -> 0.40223464
B40: E6 | C40: Limitations | D40: Care beyond benefit limits | E40: =Codebook!F45 -> Not covered | F40: ='Cohort analysis'!C6 -> 358 | G40: =COUNTIFS('Responses'!$S$6:$S$363,1,'Responses'!$AZ$6:$AZ$363,"<>") -> 358 | H40: =SUMIFS('Responses'!$CR$6:$CR$363,'Responses'!$S$6:$S$363,1) -> 109 | I40: =IFERROR(H40/G40,0) -> 0.30446927 | J40: =G40-H40-K40 -> 98 | K40: =COUNTIFS('Responses'!$AZ$6:$AZ$363,"Not sure",'Responses'!$S$6:$S$363,1) -> 151 | L40: =F40-G40 -> 0 | M40: =IFERROR(K40/G40,0) -> 0.42178771
B45: Priority item | C45: Correct %
B46: C8 | Curative-only coverage misconception | C46: =I24 -> 0.11797753 | O46: C8 | Curative-only coverage
...

Sheet Associations
B1: Back to dashboard
B2: Factors associated with overall adequacy
B3: Full-sample tests: independent of the dashboard filters. Formula-linked counts and p-values update if the scoring key changes.
B5: Associations are unadjusted, not causal. Sex uses Yates continuity correction to reproduce the report; the other core tests use uncorrected Pearson chi-square.
B7: Factor | C7: Chi-square | D7: df | E7: p-value | F7: Significant < .05 | G7: Min expected | H7: Method
B8: Sex | C8: =SUM(H17:H18) -> 0.66368397 | D8: 1 | E8: =_xlfn.CHISQ.DIST.RT(C8,D8) -> 0.41526237 | F8: =IF(E8<0.05,"Yes","No") -> No | G8: =MIN(F17:G18) -> 48.044693 | H8: Yates-corrected
B9: Year of study | C9: =SUM(H24:H27) -> 1.7474659 | D9: 3 | E9: =_xlfn.CHISQ.DIST.RT(C9,D9) -> 0.62643311 | F9: =IF(E9<0.05,"Yes","No") -> No | G9: =MIN(F24:G27) -> 11.452514 | H9: Pearson (uncorrected)
B10: Programme | C10: =SUM(H33:H37) -> 14.190747 | D10: 4 | E10: =_xlfn.CHISQ.DIST.RT(C10,D10) -> 0.0067105074 | F10: =IF(E10<0.05,"Yes","No") -> Yes | G10: =MIN(F33:G37) -> 15.363128 | H10: Pearson (uncorrected)
B11: Insurance registration | C11: =SUM(H43:H45) -> 14.346917 | D11: 2 | E11: =_xlfn.CHISQ.DIST.RT(C11,D11) -> 0.0007666667 | F11: =IF(E11<0.05,"Yes","No") -> Yes | G11: =MIN(F43:G45) -> 18.715084 | H11: Pearson (uncorrected)
B15: Sex | observed and expected counts
B16: Category | C16: Inadequate | D16: Adequate | E16: Group total | F16: Expected inadequate | G16: Expected adequate | H16: Chi-square component
B17: Female | C17: =COUNTIFS('Responses'!$E$6:$E$363,B17,'Responses'!$L$6:$L$363,0) -> 138 | D17: =COUNTIFS('Responses'!$E$6:$E$363,B17,'Responses'!$L$6:$L$363,1) -> 48 | E17: =SUM(C17:D17) -> 186 | F17: =E17*COUNTIF('Responses'!$L$6:$L$363,0)/COUNTA('Responses'!$B$6:$B$363) -> 134.04469 | G17: =E17*COUNTIF('Responses'!$L$6:$L$363,1)/COUNTA('Responses'!$B$6:$B$363) -> 51.955307 | H17: =IFERROR((MAX(0,ABS(C17-F17)-0.5)^2/F17)+(MAX(0,ABS(D17-G17)-0.5)^2/G17),0) -> 0.31886492
B18: Male | C18: =COUNTIFS('Responses'!$E$6:$E$363,B18,'Responses'!$L$6:$L$363,0) -> 120 | D18: =COUNTIFS('Responses'!$E$6:$E$363,B18,'Responses'!$L$6:$L$363,1) -> 52 | E18: =SUM(C18:D18) -> 172 | F18: =E18*COUNTIF('Responses'!$L$6:$L$363,0)/COUNTA('Responses'!$B$6:$B$363) -> 123.95531 | G18: =E18*COUNTIF('Responses'!$L$6:$L$363,1)/COUNTA('Responses'!$B$6:$B$363) -> 48.044693 | H18: =IFERROR((MAX(0,ABS(C18-F18)-0.5)^2/F18)+(MAX(0,ABS(D18-G18)-0.5)^2/G18),0) -> 0.34481905
B19: All expected cells exceed 5 in the supplied full-sample table. Review validity if you change the scoring key.
B22: Year of study | observed and expected counts
B23: Category | C23: Inadequate | D23: Adequate | E23: Group total | F23: Expected inadequate | G23: Expected adequate | H23: Chi-square component
B24: 2nd year | C24: =COUNTIFS('Responses'!$F$6:$F$363,B24,'Responses'!$L$6:$L$363,0) -> 62 | D24: =COUNTIFS('Responses'!$F$6:$F$363,B24,'Responses'!$L$6:$L$363,1) -> 19 | E24: =SUM(C24:D24) -> 81 | F24: =E24*COUNTIF('Responses'!$L$6:$L$363,0)/COUNTA('Responses'!$B$6:$B$363) -> 58.374302 | G24: =E24*COUNTIF('Responses'!$L$6:$L$363,1)/COUNTA('Responses'!$B$6:$B$363) -> 22.625698 | H24: =IFERROR((C24-F24)^2/F24+(D24-G24)^2/G24,0) -> 0.80620346
B25: 3rd year | C25: =COUNTIFS('Responses'!$F$6:$F$363,B25,'Responses'!$L$6:$L$363,0) -> 87 | D25: =COUNTIFS('Responses'!$F$6:$F$363,B25,'Responses'!$L$6:$L$363,1) -> 33 | E25: =SUM(C25:D25) -> 120 | F25: =E25*COUNTIF('Responses'!$L$6:$L$363,0)/COUNTA('Responses'!$B$6:$B$363) -> 86.480447 | G25: =E25*COUNTIF('Responses'!$L$6:$L$363,1)/COUNTA('Responses'!$B$6:$B$363) -> 33.519553 | H25: =IFERROR((C25-F25)^2/F25+(D25-G25)^2/G25,0) -> 0.011174419
B26: 4th year | C26: =COUNTIFS('Responses'!$F$6:$F$363,B26,'Responses'!$L$6:$L$363,0) -> 79 | D26: =COUNTIFS('Responses'!$F$6:$F$363,B26,'Responses'!$L$6:$L$363,1) -> 37 | E26: =SUM(C26:D26) -> 116 | F26: =E26*COUNTIF('Responses'!$L$6:$L$363,0)/COUNTA('Responses'!$B$6:$B$363) -> 83.597765 | G26: =E26*COUNTIF('Responses'!$L$6:$L$363,1)/COUNTA('Responses'!$B$6:$B$363) -> 32.402235 | H26: =IFERROR((C26-F26)^2/F26+(D26-G26)^2/G26,0) -> 0.905278
B27: 5th year or above | C27: =COUNTIFS('Responses'!$F$6:$F$363,B27,'Responses'!$L$6:$L$363,0) -> 30 | D27: =COUNTIFS('Responses'!$F$6:$F$363,B27,'Responses'!$L$6:$L$363,1) -> 11 | E27: =SUM(C27:D27) -> 41 | F27: =E27*COUNTIF('Responses'!$L$6:$L$363,0)/COUNTA('Responses'!$B$6:$B$363) -> 29.547486 | G27: =E27*COUNTIF('Responses'!$L$6:$L$363,1)/COUNTA('Responses'!$B$6:$B$363) -> 11.452514 | H27: =IFERROR((C27-F27)^2/F27+(D27-G27)^2/G27,0) -> 0.024809983
B28: All expected cells exceed 5 in the supplied full-sample table. Review validity if you change the scoring key.
B31: Programme | observed and expected counts
B32: Category | C32: Inadequate | D32: Adequate | E32: Group total | F32: Expected inadequate | G32: Expected adequate | H32: Chi-square component
B33: Medicine | C33: =COUNTIFS('Responses'!$G$6:$G$363,B33,'Responses'!$L$6:$L$363,0) -> 36 | D33: =COUNTIFS('Responses'!$G$6:$G$363,B33,'Responses'!$L$6:$L$363,1) -> 19 | E33: =SUM(C33:D33) -> 55 | F33: =E33*COUNTIF('Responses'!$L$6:$L$363,0)/COUNTA('Responses'!$B$6:$B$363) -> 39.636872 | G33: =E33*COUNTIF('Responses'!$L$6:$L$363,1)/COUNTA('Responses'!$B$6:$B$363) -> 15.363128 | H33: =IFERROR((C33-F33)^2/F33+(D33-G33)^2/G33,0) -> 1.1946469
B34: Nursing Sciences | C34: =COUNTIFS('Responses'!$G$6:$G$363,B34,'Responses'!$L$6:$L$363,0) -> 58 | D34: =COUNTIFS('Responses'!$G$6:$G$363,B34,'Responses'!$L$6:$L$363,1) -> 22 | E34: =SUM(C34:D34) -> 80 | F34: =E34*COUNTIF('Responses'!$L$6:$L$363,0)/COUNTA('Responses'!$B$6:$B$363) -> 57.653631 | G34: =E34*COUNTIF('Responses'!$L$6:$L$363,1)/COUNTA('Responses'!$B$6:$B$363) -> 22.346369 | H34: =IFERROR((C34-F34)^2/F34+(D34-G34)^2/G34,0) -> 0.0074496124
B35: Other Ridgeway Health Sciences programme | C35: =COUNTIFS('Responses'!$G$6:$G$363,B35,'Responses'!$L$6:$L$363,0) -> 57 | D35: =COUNTIFS('Responses'!$G$6:$G$363,B35,'Responses'!$L$6:$L$363,1) -> 7 | E35: =SUM(C35:D35) -> 64 | F35: =E35*COUNTIF('Responses'!$L$6:$L$363,0)/COUNTA('Responses'!$B$6:$B$363) -> 46.122905 | G35: =E35*COUNTIF('Responses'!$L$6:$L$363,1)/COUNTA('Responses'!$B$6:$B$363) -> 17.877095 | H35: =IFERROR((C35-F35)^2/F35+(D35-G35)^2/G35,0) -> 9.1831613
B36: Pharmacy | C36: =COUNTIFS('Responses'!$G$6:$G$363,B36,'Responses'!$L$6:$L$363,0) -> 47 | D36: =COUNTIFS('Responses'!$G$6:$G$363,B36,'Responses'!$L$6:$L$363,1) -> 17 | E36: =SUM(C36:D36) -> 64 | F36: =E36*COUNTIF('Responses'!$L$6:$L$363,0)/COUNTA('Responses'!$B$6:$B$363) -> 46.122905 | G36: =E36*COUNTIF('Responses'!$L$6:$L$363,1)/COUNTA('Responses'!$B$6:$B$363) -> 17.877095 | H36: =IFERROR((C36-F36)^2/F36+(D36-G36)^2/G36,0) -> 0.059711725
B37: Public Health | C37: =COUNTIFS('Responses'!$G$6:$G$363,B37,'Responses'!$L$6:$L$363,0) -> 60 | D37: =COUNTIFS('Responses'!$G$6:$G$363,B37,'Responses'!$L$6:$L$363,1) -> 35 | E37: =SUM(C37:D37) -> 95 | F37: =E37*COUNTIF('Responses'!$L$6:$L$363,0)/COUNTA('Responses'!$B$6:$B$363) -> 68.463687 | G37: =E37*COUNTIF('Responses'!$L$6:$L$363,1)/COUNTA('Responses'!$B$6:$B$363) -> 26.536313 | H37: =IFERROR((C37-F37)^2/F37+(D37-G37)^2/G37,0) -> 3.7457772
B38: All expected cells exceed 5 in the supplied full-sample table. Review validity if you change the scoring key.
B41: Insurance registration | observed and expected counts
B42: Category | C42: Inadequate | D42: Adequate | E42: Group total | F42: Expected inadequate | G42: Expected adequate | H42: Chi-square component
B43: No | C43: =COUNTIFS('Responses'!$H$6:$H$363,B43,'Responses'!$L$6:$L$363,0) -> 96 | D43: =COUNTIFS('Responses'!$H$6:$H$363,B43,'Responses'!$L$6:$L$363,1) -> 57 | E43: =SUM(C43:D43) -> 153 | F43: =E43*COUNTIF('Responses'!$L$6:$L$363,0)/COUNTA('Responses'!$B$6:$B$363) -> 110.26257 | G43: =E43*COUNTIF('Responses'!$L$6:$L$363,1)/COUNTA('Responses'!$B$6:$B$363) -> 42.73743 | H43: =IFERROR((C43-F43)^2/F43+(D43-G43)^2/G43,0) -> 6.6046603
B44: Not sure | C44: =COUNTIFS('Responses'!$H$6:$H$363,B44,'Responses'!$L$6:$L$363,0) -> 58 | D44: =COUNTIFS('Responses'!$H$6:$H$363,B44,'Responses'!$L$6:$L$363,1) -> 9 | E44: =SUM(C44:D44) -> 67 | F44: =E44*COUNTIF('Responses'!$L$6:$L$363,0)/COUNTA('Responses'!$B$6:$B$363) -> 48.284916 | G44: =E44*COUNTIF('Responses'!$L$6:$L$363,1)/COUNTA('Responses'!$B$6:$B$363) -> 18.715084 | H44: =IFERROR((C44-F44)^2/F44+(D44-G44)^2/G44,0) -> 6.9978503
B45: Yes | C45: =COUNTIFS('Responses'!$H$6:$H$363,B45,'Responses'!$L$6:$L$363,0) -> 104 | D45: =COUNTIFS('Responses'!$H$6:$H$363,B45,'Responses'!$L$6:$L$363,1) -> 34 | E45: =SUM(C45:D45) -> 138 | F45: =E45*COUNTIF('Responses'!$L$6:$L$363,0)/COUNTA('Responses'!$B$6:$B$363) -> 99.452514 | G45: =E45*COUNTIF('Responses'!$L$6:$L$363,1)/COUNTA('Responses'!$B$6:$B$363) -> 38.547486 | H45: =IFERROR((C45-F45)^2/F45+(D45-G45)^2/G45,0) -> 0.74440625
B46: All expected cells exceed 5 in the supplied full-sample table. Review validity if you change the scoring key.

Sheet Responses
B1: Back to dashboard
B2: Survey responses & derived scores
B3: Original file preserved. Text trimmed; Boolean true/false cells normalised to text. Filter this table to inspect individual records.
B5: ID | C5: Timestamp | D5: Age as reported | E5: Sex | F5: Year of study | G5: Programme | H5: Insurance registered | I5: Health score /10 | J5: NHIMA score /9 | K5: Overall score /19 | L5: Adequate overall (1/0) | M5: B/C complete (1/0) | N5: Benefits score /8 | O5: Limitations score /6 | P5: Benefits + limits /14 | Q5: Wants more information | R5: Most useful source (normalised) | S5: Selected cohort (1/0) | T5: B1 | U5: B2 | V5: B3 | W5: B4 | X5: B5 | Y5: B6 | Z5: B7 | AA5: B8 | AB5: B9 | AC5: B10 | AD5: C2 | AE5: C3 | AF5: C4 | AG5: C5 | AH5: C6 | AI5: C7 | AJ5: C8 | AK5: C9 | AL5: C10 | AM5: D1 | AN5: D2 | AO5: D3 | AP5: D4 | AQ5: D5 | AR5: D6 | AS5: D7 | AT5: D8 | AU5: E1 | AV5: E2 | AW5: E3 | AX5: E4 | AY5: E5 | AZ5: E6 | BA5: Information sources (multi-select) | BB5: Most useful source (original) | BC5: Radio / TV | BD5: Print media | BE5: Social media | BF5: Family | BG5: Friends / students | BH5: Coursework / lectures | BI5: NHIMA outreach / offices | BJ5: Health facility staff | BK5: No information source | BL5: Score B1 | BM5: Score B2 | BN5: Score B3 | BO5: Score B4 | BP5: Score B5 | BQ5: Score B6 | BR5: Score B7 | BS5: Score B8 | BT5: Score B9 | BU5: Score B10 | BV5: Score C2 | BW5: Score C3 | BX5: Score C4 | BY5: Score C5 | BZ5: Score C6 | CA5: Score C7 | CB5: Score C8 | CC5: Score C9 | CD5: Score C10 | CE5: Score D1 | CF5: Score D2 | CG5: Score D3 | CH5: Score D4 | CI5: Score D5 | CJ5: Score D6 | CK5: Score D7 | CL5: Score D8 | CM5: Score E1 | CN5: Score E2 | CO5: Score E3 | CP5: Score E4 | CQ5: Score E5 | CR5: Score E6
B6: 1 | C6: 46255.455 | D6: 28 | E6: Male | F6: 3rd year | G6: Nursing Sciences | H6: Yes | I6: =SUM(BL6:BU6) -> 8 | J6: =IF(COUNT(BV6:CD6)=9,SUM(BV6:CD6),"") -> 7 | K6: =SUM(BL6:CD6) -> 15 | L6: =--(K6>='Codebook'!$C$8) -> 1 | M6: =--(COUNT(BL6:CD6)=19) -> 1 | N6: =SUM(CE6:CL6) -> 5 | O6: =SUM(CM6:CR6) -> 4 | P6: =N6+O6 -> 9 | Q6: Yes | R6: Social media | S6: =--OR(Overview!$B$6="All",E6=Overview!$B$6)*--OR(Overview!$F$6="All",F6=Overview!$F$6)*--OR(Overview!$J$6="All",G6=Overview!$J$6)*--OR(Overview!$N$6="All",H6=Overview!$N$6) -> 1 | T6: True | U6: Not sure | V6: True | W6: True | X6: True | Y6: False | Z6: True | AA6: True | AB6: False | AC6: True | AD6: True | AE6: True | AF6: False | AG6: False | AH6: True | AI6: False | AJ6: True | AK6: True | AL6: False | AM6: Not covered | AN6: Not covered | AO6: Covered | AP6: Covered | AQ6: Not covered | AR6: Covered | AS6: Covered | AT6: Covered | AU6: Covered | AV6: Covered | AW6: Not covered | AX6: Not covered | AY6: Not covered | AZ6: Not covered | BA6: Radio or television, Social media (e.g. Facebook, WhatsApp, YouTube, X/Twitter), School coursework or lectures, Health facility staff | BB6: socil media | BC6: =--ISNUMBER(SEARCH("Radio or television",BA6)) -> 1 | BD6: =--ISNUMBER(SEARCH("Newspapers or print media",BA6)) -> 0 | BE6: =--ISNUMBER(SEARCH("Social media (e.g. Facebook, WhatsApp, YouTube, X/Twitter)",BA6)) -> 1 | BF6: =--ISNUMBER(SEARCH("Family members",BA6)) -> 0 | BG6: =--ISNUMBER(SEARCH("Friends or fellow students",BA6)) -> 0 | BH6: =--ISNUMBER(SEARCH("School coursework or lectures",BA6)) -> 1 | BI6: =--ISNUMBER(SEARCH("NHIMA outreach activities or NHIMA offices",BA6)) -> 0 | BJ6: =--ISNUMBER(SEARCH("Health facility staff",BA6)) -> 1 | BK6: =--ISNUMBER(SEARCH("not received information",BA6)) -> 0 | BL6: =IF(T6="","",--(T6='Codebook'!$F$13)) -> 1 | BM6: =IF(U6="","",--(U6='Codebook'!$F$14)) -> 0 | BN6: =IF(V6="","",--(V6='Codebook'!$F$15)) -> 0 | BO6: =IF(W6="","",--(W6='Codebook'!$F$16)) -> 1 | BP6: =IF(X6="","",--(X6='Codebook'!$F$17)) -> 1 | BQ6: =IF(Y6="","",--(Y6='Codebook'!$F$18)) -> 1 | BR6: =IF(Z6="","",--(Z6='Codebook'!$F$19)) -> 1 | BS6: =IF(AA6="","",--(AA6='Codebook'!$F$20)) -> 1 | BT6: =IF(AB6="","",--(AB6='Codebook'!$F$21)) -> 1 | BU6: =IF(AC6="","",--(AC6='Codebook'!$F$22)) -> 1 | BV6: =IF(AD6="","",--(AD6='Codebook'!$F$23)) -> 1 | BW6: =IF(AE6="","",--(AE6='Codebook'!$F$24)) -> 1 | BX6: =IF(AF6="","",--(AF6='Codebook'!$F$25)) -> 1 | BY6: =IF(AG6="","",--(AG6='Codebook'!$F$26)) -> 0 | BZ6: =IF(AH6="","",--(AH6='Codebook'!$F$27)) -> 1 | CA6: =IF(AI6="","",--(AI6='Codebook'!$F$28)) -> 1 | CB6: =IF(AJ6="","",--(AJ6='Codebook'!$F$29)) -> 0 | CC6: =IF(AK6="","",--(AK6='Codebook'!$F$30)) -> 1 | CD6: =IF(AL6="","",--(AL6='Codebook'!$F$31)) -> 1 | CE6: =IF(AM6="","",--(AM6='Codebook'!$F$32)) -> 0 | CF6: =IF(AN6="","",--(AN6='Codebook'!$F$33)) -> 0 | CG6: =IF(AO6="","",--(AO6='Codebook'!$F$34)) -> 1 | CH6: =IF(AP6="","",--(AP6='Codebook'!$F$35)) -> 1 | CI6: =IF(AQ6="","",--(AQ6='Codebook'!$F$36)) -> 0 | CJ6: =IF(AR6="","",--(AR6='Codebook'!$F$37)) -> 1 | CK6: =IF(AS6="","",--(AS6='Codebook'!$F$38)) -> 1 | CL6: =IF(AT6="","",--(AT6='Codebook'!$F$39)) -> 1 | CM6: =IF(AU6="","",--(AU6='Codebook'!$F$40)) -> 0 | CN6: =IF(AV6="","",--(AV6='Codebook'!$F$41)) -> 0 | CO6: =IF(AW6="","",--(AW6='Codebook'!$F$42)) -> 1 | CP6: =IF(AX6="","",--(AX6='Codebook'!$F$43)) -> 1 | CQ6: =IF(AY6="","",--(AY6='Codebook'!$F$44)) -> 1 | CR6: =IF(AZ6="","",--(AZ6='Codebook'!$F$45)) -> 1
B7: 2 | C7: 46255.516 | D7: 23 | E7: Male | F7: 4th year | G7: Public Health | H7: Yes | I7: =SUM(BL7:BU7) -> 8 | J7: =IF(COUNT(BV7:CD7)=9,SUM(BV7:CD7),"") -> 6 | K7: =SUM(BL7:CD7) -> 14 | L7: =--(K7>='Codebook'!$C$8) -> 1 | M7: =--(COUNT(BL7:CD7)=19) -> 1 | N7: =SUM(CE7:CL7) -> 4 | O7: =SUM(CM7:CR7) -> 6 | P7: =N7+O7 -> 10 | Q7: Yes | R7: Radio / TV | S7: =--OR(Overview!$B$6="All",E7=Overview!$B$6)*--OR(Overview!$F$6="All",F7=Overview!$F$6)*--OR(Overview!$J$6="All",G7=Overview!$J$6)*--OR(Overview!$N$6="All",H7=Overview!$N$6) -> 1 | T7: True | U7: True | V7: True | W7: True | X7: True | Y7: False | Z7: True | AA7: True | AB7: False | AC7: True | AD7: True | AE7: True | AF7: False | AG7: True | AH7: True | AI7: Not sure | AJ7: Not sure | AK7: Not sure | AL7: False | AM7: Not sure | AN7: Covered | AO7: Not sure | AP7: Not covered | AQ7: Not sure | AR7: Covered | AS7: Covered | AT7: Covered | AU7: Not covered | AV7: Not covered | AW7: Not covered | AX7: Not covered | AY7: Not covered | AZ7: Not covered | BA7: Radio or television, Social media (e.g. Facebook, WhatsApp, YouTube, X/Twitter), Family members, Friends or fellow students, School coursework or lectures | BB7: tv | BC7: =--ISNUMBER(SEARCH("Radio or television",BA7)) -> 1 | BD7: =--ISNUMBER(SEARCH("Newspapers or print media",BA7)) -> 0 | BE7: =--ISNUMBER(SEARCH("Social media (e.g. Facebook, WhatsApp, YouTube, X/Twitter)",BA7)) -> 1 | BF7: =--ISNUMBER(SEARCH("Family members",BA7)) -> 1 | BG7: =--ISNUMBER(SEARCH("Friends or fellow students",BA7)) -> 1 | BH7: =--ISNUMBER(SEARCH("School coursework or lectures",BA7)) -> 1 | BI7: =--ISNUMBER(SEARCH("NHIMA outreach activities or NHIMA offices",BA7)) -> 0 | BJ7: =--ISNUMBER(SEARCH("Health facility staff",BA7)) -> 0 | BK7: =--ISNUMBER(SEARCH("not received information",BA7)) -> 0 | BL7: =IF(T7="","",--(T7='Codebook'!$F$13)) -> 1 | BM7: =IF(U7="","",--(U7='Codebook'!$F$14)) -> 0 | BN7: =IF(V7="","",--(V7='Codebook'!$F$15)) -> 0 | BO7: =IF(W7="","",--(W7='Codebook'!$F$16)) -> 1 | BP7: =IF(X7="","",--(X7='Codebook'!$F$17)) -> 1 | BQ7: =IF(Y7="","",--(Y7='Codebook'!$F$18)) -> 1 | BR7: =IF(Z7="","",--(Z7='Codebook'!$F$19)) -> 1 | BS7: =IF(AA7="","",--(AA7='Codebook'!$F$20)) -> 1 | BT7: =IF(AB7="","",--(AB7='Codebook'!$F$21)) -> 1 | BU7: =IF(AC7="","",--(AC7='Codebook'!$F$22)) -> 1 | BV7: =IF(AD7="","",--(AD7='Codebook'!$F$23)) -> 1 | BW7: =IF(AE7="","",--(AE7='Codebook'!$F$24)) -> 1 | BX7: =IF(AF7="","",--(AF7='Codebook'!$F$25)) -> 1 | BY7: =IF(AG7="","",--(AG7='Codebook'!$F$26)) -> 1 | BZ7: =IF(AH7="","",--(AH7='Codebook'!$F$27)) -> 1 | CA7: =IF(AI7="","",--(AI7='Codebook'!$F$28)) -> 0 | CB7: =IF(AJ7="","",--(AJ7='Codebook'!$F$29)) -> 0 | CC7: =IF(AK7="","",--(AK7='Codebook'!$F$30)) -> 0 | CD7: =IF(AL7="","",--(AL7='Codebook'!$F$31)) -> 1 | CE7: =IF(AM7="","",--(AM7='Codebook'!$F$32)) -> 0 | CF7: =IF(AN7="","",--(AN7='Codebook'!$F$33)) -> 1 | CG7: =IF(AO7="","",--(AO7='Codebook'!$F$34)) -> 0 | CH7: =IF(AP7="","",--(AP7='Codebook'!$F$35)) -> 0 | CI7: =IF(AQ7="","",--(AQ7='Codebook'!$F$36)) -> 0 | CJ7: =IF(AR7="","",--(AR7='Codebook'!$F$37)) -> 1 | CK7: =IF(AS7="","",--(AS7='Codebook'!$F$38)) -> 1 | CL7: =IF(AT7="","",--(AT7='Codebook'!$F$39)) -> 1 | CM7: =IF(AU7="","",--(AU7='Codebook'!$F$40)) -> 1 | CN7: =IF(AV7="","",--(AV7='Codebook'!$F$41)) -> 1 | CO7: =IF(AW7="","",--(AW7='Codebook'!$F$42)) -> 1 | CP7: =IF(AX7="","",--(AX7='Codebook'!$F$43)) -> 1 | CQ7: =IF(AY7="","",--(AY7='Codebook'!$F$44)) -> 1 | CR7: =IF(AZ7="","",--(AZ7='Codebook'!$F$45)) -> 1
B8: 3 | C8: 46255.542 | D8: 23 years | E8: Female | F8: 4th year | G8: Public Health | H8: No | I8: =SUM(BL8:BU8) -> 9 | J8: =IF(COUNT(BV8:CD8)=9,SUM(BV8:CD8),"") -> 5 | K8: =SUM(BL8:CD8) -> 14 | L8: =--(K8>='Codebook'!$C$8) -> 1 | M8: =--(COUNT(BL8:CD8)=19) -> 1 | N8: =SUM(CE8:CL8) -> 5 | O8: =SUM(CM8:CR8) -> 1 | P8: =N8+O8 -> 6 | Q8: Yes | R8: Coursework / lectures | S8: =--OR(Overview!$B$6="All",E8=Overview!$B$6)*--OR(Overview!$F$6="All",F8=Overview!$F$6)*--OR(Overview!$J$6="All",G8=Overview!$J$6)*--OR(Overview!$N$6="All",H8=Overview!$N$6) -> 1 | T8: True | U8: True | V8: False | W8: True | X8: True | Y8: False | Z8: True | AA8: True | AB8: False | AC8: True | AD8: Not sure | AE8: Not sure | AF8: False | AG8: False | AH8: True | AI8: False | AJ8: True | AK8: True | AL8: False | AM8: Not sure | AN8: Covered | AO8: Covered | AP8: Covered | AQ8: Not covered | AR8: Covered | AS8: Not covered | AT8: Covered | AU8: Not sure | AV8: Not covered | AW8: Not sure | AX8: Not sure | AY8: Not sure | AZ8: Not sure | BA8: Social media (e.g. Facebook, WhatsApp, YouTube, X/Twitter), Family members, Friends or fellow students, School coursework or lectures, Health facility staff | BB8: School | BC8: =--ISNUMBER(SEARCH("Radio or television",BA8)) -> 0 | BD8: =--ISNUMBER(SEARCH("Newspapers or print media",BA8)) -> 0 | BE8: =--ISNUMBER(SEARCH("Social media (e.g. Facebook, WhatsApp, YouTube, X/Twitter)",BA8)) -> 1 | BF8: =--ISNUMBER(SEARCH("Family members",BA8)) -> 1 | BG8: =--ISNUMBER(SEARCH("Friends or fellow students",BA8)) -> 1 | BH8: =--ISNUMBER(SEARCH("School coursework or lectures",BA8)) -> 1 | BI8: =--ISNUMBER(SEARCH("NHIMA outreach activities or NHIMA offices",BA8)) -> 0 | BJ8: =--ISNUMBER(SEARCH("Health facility staff",BA8)) -> 1 | BK8: =--ISNUMBER(SEARCH("not received information",BA8)) -> 0 | BL8: =IF(T8="","",--(T8='Codebook'!$F$13)) -> 1 | BM8: =IF(U8="","",--(U8='Codebook'!$F$14)) -> 0 | BN8: =IF(V8="","",--(V8='Codebook'!$F$15)) -> 1 | BO8: =IF(W8="","",--(W8='Codebook'!$F$16)) -> 1 | BP8: =IF(X8="","",--(X8='Codebook'!$F$17)) -> 1 | BQ8: =IF(Y8="","",--(Y8='Codebook'!$F$18)) -> 1 | BR8: =IF(Z8="","",--(Z8='Codebook'!$F$19)) -> 1 | BS8: =IF(AA8="","",--(AA8='Codebook'!$F$20)) -> 1 | BT8: =IF(AB8="","",--(AB8='Codebook'!$F$21)) -> 1 | BU8: =IF(AC8="","",--(AC8='Codebook'!$F$22)) -> 1 | BV8: =IF(AD8="","",--(AD8='Codebook'!$F$23)) -> 0 | BW8: =IF(AE8="","",--(AE8='Codebook'!$F$24)) -> 0 | BX8: =IF(AF8="","",--(AF8='Codebook'!$F$25)) -> 1 | BY8: =IF(AG8="","",--(AG8='Codebook'!$F$26)) -> 0 | BZ8: =IF(AH8="","",--(AH8='Codebook'!$F$27)) -> 1 | CA8: =IF(AI8="","",--(AI8='Codebook'!$F$28)) -> 1 | CB8: =IF(AJ8="","",--(AJ8='Codebook'!$F$29)) -> 0 | CC8: =IF(AK8="","",--(AK8='Codebook'!$F$30)) -> 1 | CD8: =IF(AL8="","",--(AL8='Codebook'!$F$31)) -> 1 | CE8: =IF(AM8="","",--(AM8='Codebook'!$F$32)) -> 0 | CF8: =IF(AN8="","",--(AN8='Codebook'!$F$33)) -> 1 | CG8: =IF(AO8="","",--(AO8='Codebook'!$F$34)) -> 1 | CH8: =IF(AP8="","",--(AP8='Codebook'!$F$35)) -> 1 | CI8: =IF(AQ8="","",--(AQ8='Codebook'!$F$36)) -> 0 | CJ8: =IF(AR8="","",--(AR8='Codebook'!$F$37)) -> 1 | CK8: =IF(AS8="","",--(AS8='Codebook'!$F$38)) -> 0 | CL8: =IF(AT8="","",--(AT8='Codebook'!$F$39)) -> 1 | CM8: =IF(AU8="","",--(AU8='Codebook'!$F$40)) -> 0 | CN8: =IF(AV8="","",--(AV8='Codebook'!$F$41)) -> 1 | CO8: =IF(AW8="","",--(AW8='Codebook'!$F$42)) -> 0 | CP8: =IF(AX8="","",--(AX8='Codebook'!$F$43)) -> 0 | CQ8: =IF(AY8="","",--(AY8='Codebook'!$F$44)) -> 0 | CR8: =IF(AZ8="","",--(AZ8='Codebook'!$F$45)) -> 0
B9: 4 | C9: 46259.432 | D9: 23 | E9: Female | F9: 4th year | G9: Public Health | H9: No | I9: =SUM(BL9:BU9) -> 7 | J9: =IF(COUNT(BV9:CD9)=9,SUM(BV9:CD9),"") -> 6 | K9: =SUM(BL9:CD9) -> 13 | L9: =--(K9>='Codebook'!$C$8) -> 1 | M9: =--(COUNT(BL9:CD9)=19) -> 1 | N9: =SUM(CE9:CL9) -> 6 | O9: =SUM(CM9:CR9) -> 3 | P9: =N9+O9 -> 9 | Q9: Yes | R9: Friends / students | S9: =--OR(Overview!$B$6="All",E9=Overview!$B$6)*--OR(Overview!$F$6="All",F9=Overview!$F$6)*--OR(Overview!$J$6="All",G9=Overview!$J$6)*--OR(Overview!$N$6="All",H9=Overview!$N$6) -> 1 | T9: True | U9: Not sure | V9: False | W9: True | X9: True | Y9: Not sure | Z9: True | AA9: True | AB9: Not sure | AC9: True | AD9: True | AE9: True | AF9: False | AG9: Not sure | AH9: True | AI9: True | AJ9: Not sure | AK9: True | AL9: False | AM9: Not covered | AN9: Covered | AO9: Covered | AP9: Covered | AQ9: Not sure | AR9: Covered | AS9: Covered | AT9: Covered | AU9: Covered | AV9: Not covered | AW9: Not covered | AX9: Not sure | AY9: Not covered | AZ9: Covered | BA9: School coursework or lectures | BB9: From friends | BC9: =--ISNUMBER(SEARCH("Radio or television",BA9)) -> 0 | BD9: =--ISNUMBER(SEARCH("Newspapers or print media",BA9)) -> 0 | BE9: =--ISNUMBER(SEARCH("Social media (e.g. Facebook, WhatsApp, YouTube, X/Twitter)",BA9)) -> 0 | BF9: =--ISNUMBER(SEARCH("Family members",BA9)) -> 0 | BG9: =--ISNUMBER(SEARCH("Friends or fellow students",BA9)) -> 0 | BH9: =--ISNUMBER(SEARCH("School coursework or lectures",BA9)) -> 1 | BI9: =--ISNUMBER(SEARCH("NHIMA outreach activities or NHIMA offices",BA9)) -> 0 | BJ9: =--ISNUMBER(SEARCH("Health facility staff",BA9)) -> 0 | BK9: =--ISNUMBER(SEARCH("not received information",BA9)) -> 0 | BL9: =IF(T9="","",--(T9='Codebook'!$F$13)) -> 1 | BM9: =IF(U9="","",--(U9='Codebook'!$F$14)) -> 0 | BN9: =IF(V9="","",--(V9='Codebook'!$F$15)) -> 1 | BO9: =IF(W9="","",--(W9='Codebook'!$F$16)) -> 1 | BP9: =IF(X9="","",--(X9='Codebook'!$F$17)) -> 1 | BQ9: =IF(Y9="","",--(Y9='Codebook'!$F$18)) -> 0 | BR9: =IF(Z9="","",--(Z9='Codebook'!$F$19)) -> 1 | BS9: =IF(AA9="","",--(AA9='Codebook'!$F$20)) -> 1 | BT9: =IF(AB9="","",--(AB9='Codebook'!$F$21)) -> 0 | BU9: =IF(AC9="","",--(AC9='Codebook'!$F$22)) -> 1 | BV9: =IF(AD9="","",--(AD9='Codebook'!$F$23)) -> 1 | BW9: =IF(AE9="","",--(AE9='Codebook'!$F$24)) -> 1 | BX9: =IF(AF9="","",--(AF9='Codebook'!$F$25)) -> 1 | BY9: =IF(AG9="","",--(AG9='Codebook'!$F$26)) -> 0 | BZ9: =IF(AH9="","",--(AH9='Codebook'!$F$27)) -> 1 | CA9: =IF(AI9="","",--(AI9='Codebook'!$F$28)) -> 0 | CB9: =IF(AJ9="","",--(AJ9='Codebook'!$F$29)) -> 0 | CC9: =IF(AK9="","",--(AK9='Codebook'!$F$30)) -> 1 | CD9: =IF(AL9="","",--(AL9='Codebook'!$F$31)) -> 1 | CE9: =IF(AM9="","",--(AM9='Codebook'!$F$32)) -> 0 | CF9: =IF(AN9="","",--(AN9='Codebook'!$F$33)) -> 1 | CG9: =IF(AO9="","",--(AO9='Codebook'!$F$34)) -> 1 | CH9: =IF(AP9="","",--(AP9='Codebook'!$F$35)) -> 1 | CI9: =IF(AQ9="","",--(AQ9='Codebook'!$F$36)) -> 0 | CJ9: =IF(AR9="","",--(AR9='Codebook'!$F$37)) -> 1 | CK9: =IF(AS9="","",--(AS9='Codebook'!$F$38)) -> 1 | CL9: =IF(AT9="","",--(AT9='Codebook'!$F$39)) -> 1 | CM9: =IF(AU9="","",--(AU9='Codebook'!$F$40)) -> 0 | CN9: =IF(AV9="","",--(AV9='Codebook'!$F$41)) -> 1 | CO9: =IF(AW9="","",--(AW9='Codebook'!$F$42)) -> 1 | CP9: =IF(AX9="","",--(AX9='Codebook'!$F$43)) -> 0 | CQ9: =IF(AY9="","",--(AY9='Codebook'!$F$44)) -> 1 | CR9: =IF(AZ9="","",--(AZ9='Codebook'!$F$45)) -> 0
B10: 5 | C10: 46259.537 | D10: 23 | E10: Male | F10: 2nd year | G10: Nursing Sciences | H10: No | I10: =SUM(BL10:BU10) -> 7 | J10: =IF(COUNT(BV10:CD10)=9,SUM(BV10:CD10),"") -> 5 | K10: =SUM(BL10:CD10) -> 12 | L10: =--(K10>='Codebook'!$C$8) -> 1 | M10: =--(COUNT(BL10:CD10)=19) -> 1 | N10: =SUM(CE10:CL10) -> 3 | O10: =SUM(CM10:CR10) -> 2 | P10: =N10+O10 -> 5 | Q10: Yes | R10: Other / unclear | S10: =--OR(Overview!$B$6="All",E10=Overview!$B$6)*--OR(Overview!$F$6="All",F10=Overview!$F$6)*--OR(Overview!$J$6="All",G10=Overview!$J$6)*--OR(Overview!$N$6="All",H10=Overview!$N$6) -> 1 | T10: True | U10: Not sure | V10: False | W10: True | X10: True | Y10: False | Z10: True | AA10: True | AB10: Not sure | AC10: Not sure | AD10: Not sure | AE10: True | AF10: False | AG10: Not sure | AH10: True | AI10: False | AJ10: Not sure | AK10: Not sure | AL10: False | AM10: Covered | AN10: Not sure | AO10: Not sure | AP10: Covered | AQ10: Not sure | AR10: Covered | AS10: Not covered | AT10: Not sure | AU10: Not sure | AV10: Not sure | AW10: Not sure | AX10: Not covered | AY10: Not covered | AZ10: Not sure | BA10: School coursework or lectures | BB10: Reproductive health | BC10: =--ISNUMBER(SEARCH("Radio or television",BA10)) -> 0 | BD10: =--ISNUMBER(SEARCH("Newspapers or print media",BA10)) -> 0 | BE10: =--ISNUMBER(SEARCH("Social media (e.g. Facebook, WhatsApp, YouTube, X/Twitter)",BA10)) -> 0 | BF10: =--ISNUMBER(SEARCH("Family members",BA10)) -> 0 | BG10: =--ISNUMBER(SEARCH("Friends or fellow students",BA10)) -> 0 | BH10: =--ISNUMBER(SEARCH("School coursework or lectures",BA10)) -> 1 | BI10: =--ISNUMBER(SEARCH("NHIMA outreach activities or NHIMA offices",BA10)) -> 0 | BJ10: =--ISNUMBER(SEARCH("Health facility staff",BA10)) -> 0 | BK10: =--ISNUMBER(SEARCH("not received information",BA10)) -> 0 | BL10: =IF(T10="","",--(T10='Codebook'!$F$13)) -> 1 | BM10: =IF(U10="","",--(U10='Codebook'!$F$14)) -> 0 | BN10: =IF(V10="","",--(V10='Codebook'!$F$15)) -> 1 | BO10: =IF(W10="","",--(W10='Codebook'!$F$16)) -> 1 | BP10: =IF(X10="","",--(X10='Codebook'!$F$17)) -> 1 | BQ10: =IF(Y10="","",--(Y10='Codebook'!$F$18)) -> 1 | BR10: =IF(Z10="","",--(Z10='Codebook'!$F$19)) -> 1 | BS10: =IF(AA10="","",--(AA10='Codebook'!$F$20)) -> 1 | BT10: =IF(AB10="","",--(AB10='Codebook'!$F$21)) -> 0 | BU10: =IF(AC10="","",--(AC10='Codebook'!$F$22)) -> 0 | BV10: =IF(AD10="","",--(AD10='Codebook'!$F$23)) -> 0 | BW10: =IF(AE10="","",--(AE10='Codebook'!$F$24)) -> 1 | BX10: =IF(AF10="","",--(AF10='Codebook'!$F$25)) -> 1 | BY10: =IF(AG10="","",--(AG10='Codebook'!$F$26)) -> 0 | BZ10: =IF(AH10="","",--(AH10='Codebook'!$F$27)) -> 1 | CA10: =IF(AI10="","",--(AI10='Codebook'!$F$28)) -> 1 | CB10: =IF(AJ10="","",--(AJ10='Codebook'!$F$29)) -> 0 | CC10: =IF(AK10="","",--(AK10='Codebook'!$F$30)) -> 0 | CD10: =IF(AL10="","",--(AL10='Codebook'!$F$31)) -> 1 | CE10: =IF(AM10="","",--(AM10='Codebook'!$F$32)) -> 1 | CF10: =IF(AN10="","",--(AN10='Codebook'!$F$33)) -> 0 | CG10: =IF(AO10="","",--(AO10='Codebook'!$F$34)) -> 0 | CH10: =IF(AP10="","",--(AP10='Codebook'!$F$35)) -> 1 | CI10: =IF(AQ10="","",--(AQ10='Codebook'!$F$36)) -> 0 | CJ10: =IF(AR10="","",--(AR10='Codebook'!$F$37)) -> 1 | CK10: =IF(AS10="","",--(AS10='Codebook'!$F$38)) -> 0 | CL10: =IF(AT10="","",--(AT10='Codebook'!$F$39)) -> 0 | CM10: =IF(AU10="","",--(AU10='Codebook'!$F$40)) -> 0 | CN10: =IF(AV10="","",--(AV10='Codebook'!$F$41)) -> 0 | CO10: =IF(AW10="","",--(AW10='Codebook'!$F$42)) -> 0 | CP10: =IF(AX10="","",--(AX10='Codebook'!$F$43)) -> 1 | CQ10: =IF(AY10="","",--(AY10='Codebook'!$F$44)) -> 1 | CR10: =IF(AZ10="","",--(AZ10='Codebook'!$F$45)) -> 0
B11: 6 | C11: 46259.57 | D11: 25 | E11: Male | F11: 4th year | G11: Pharmacy | H11: No | I11: =SUM(BL11:BU11) -> 8 | J11: =IF(COUNT(BV11:CD11)=9,SUM(BV11:CD11),"") -> 6 | K11: =SUM(BL11:CD11) -> 14 | L11: =--(K11>='Codebook'!$C$8) -> 1 | M11: =--(COUNT(BL11:CD11)=19) -> 1 | N11: =SUM(CE11:CL11) -> 7 | O11: =SUM(CM11:CR11) -> 5 | P11: =N11+O11 -> 12 | Q11: Yes | R11: Multiple sources | S11: =--OR(Overview!$B$6="All",E11=Overview!$B$6)*--OR(Overview!$F$6="All",F11=Overview!$F$6)*--OR(Overview!$J$6="All",G11=Overview!$J$6)*--OR(Overview!$N$6="All",H11=Overview!$N$6) -> 1 | T11: True | U11: True | V11: False | W11: True | X11: True | Y11: True | Z11: True | AA11: True | AB11: False | AC11: True | AD11: True | AE11: True | AF11: True | AG11: True | AH11: True | AI11: True | AJ11: False | AK11: True | AL11: True | AM11: Covered | AN11: Covered | AO11: Covered | AP11: Covered | AQ11: Covered | AR11: Covered | AS11: Not covered | AT11: Covered | AU11: Covered | AV11: Not covered | AW11: Not covered | AX11: Not covered | AY11: Not covered | AZ11: Not covered | BA11: Radio or television, Newspapers or print media, Family members, Friends or fellow students, School coursework or lectures, NHIMA outreach activities or NHIMA offices | BB11: My family and friends | BC11: =--ISNUMBER(SEARCH("Radio or television",BA11)) -> 1 | BD11: =--ISNUMBER(SEARCH("Newspapers or print media",BA11)) -> 1 | BE11: =--ISNUMBER(SEARCH("Social media (e.g. Facebook, WhatsApp, YouTube, X/Twitter)",BA11)) -> 0 | BF11: =--ISNUMBER(SEARCH("Family members",BA11)) -> 1 | BG11: =--ISNUMBER(SEARCH("Friends or fellow students",BA11)) -> 1 | BH11: =--ISNUMBER(SEARCH("School coursework or lectures",BA11)) -> 1 | BI11: =--ISNUMBER(SEARCH("NHIMA outreach activities or NHIMA offices",BA11)) -> 1 | BJ11: =--ISNUMBER(SEARCH("Health facility staff",BA11)) -> 0 | BK11: =--ISNUMBER(SEARCH("not received information",BA11)) -> 0 | BL11: =IF(T11="","",--(T11='Codebook'!$F$13)) -> 1 | BM11: =IF(U11="","",--(U11='Codebook'!$F$14)) -> 0 | BN11: =IF(V11="","",--(V11='Codebook'!$F$15)) -> 1 | BO11: =IF(W11="","",--(W11='Codebook'!$F$16)) -> 1 | BP11: =IF(X11="","",--(X11='Codebook'!$F$17)) -> 1 | BQ11: =IF(Y11="","",--(Y11='Codebook'!$F$18)) -> 0 | BR11: =IF(Z11="","",--(Z11='Codebook'!$F$19)) -> 1 | BS11: =IF(AA11="","",--(AA11='Codebook'!$F$20)) -> 1 | BT11: =IF(AB11="","",--(AB11='Codebook'!$F$21)) -> 1 | BU11: =IF(AC11="","",--(AC11='Codebook'!$F$22)) -> 1 | BV11: =IF(AD11="","",--(AD11='Codebook'!$F$23)) -> 1 | BW11: =IF(AE11="","",--(AE11='Codebook'!$F$24)) -> 1 | BX11: =IF(AF11="","",--(AF11='Codebook'!$F$25)) -> 0 | BY11: =IF(AG11="","",--(AG11='Codebook'!$F$26)) -> 1 | BZ11: =IF(AH11="","",--(AH11='Codebook'!$F$27)) -> 1 | CA11: =IF(AI11="","",--(AI11='Codebook'!$F$28)) -> 0 | CB11: =IF(AJ11="","",--(AJ11='Codebook'!$F$29)) -> 1 | CC11: =IF(AK11="","",--(AK11='Codebook'!$F$30)) -> 1 | CD11: =IF(AL11="","",--(AL11='Codebook'!$F$31)) -> 0 | CE11: =IF(AM11="","",--(AM11='Codebook'!$F$32)) -> 1 | CF11: =IF(AN11="","",--(AN11='Codebook'!$F$33)) -> 1 | CG11: =IF(AO11="","",--(AO11='Codebook'!$F$34)) -> 1 | CH11: =IF(AP11="","",--(AP11='Codebook'!$F$35)) -> 1 | CI11: =IF(AQ11="","",--(AQ11='Codebook'!$F$36)) -> 1 | CJ11: =IF(AR11="","",--(AR11='Codebook'!$F$37)) -> 1 | CK11: =IF(AS11="","",--(AS11='Codebook'!$F$38)) -> 0 | CL11: =IF(AT11="","",--(AT11='Codebook'!$F$39)) -> 1 | CM11: =IF(AU11="","",--(AU11='Codebook'!$F$40)) -> 0 | CN11: =IF(AV11="","",--(AV11='Codebook'!$F$41)) -> 1 | CO11: =IF(AW11="","",--(AW11='Codebook'!$F$42)) -> 1 | CP11: =IF(AX11="","",--(AX11='Codebook'!$F$43)) -> 1 | CQ11: =IF(AY11="","",--(AY11='Codebook'!$F$44)) -> 1 | CR11: =IF(AZ11="","",--(AZ11='Codebook'!$F$45)) -> 1
